<?xml version="1.0"?>
<mujoco xmlns:xacro="http://ros.org/wiki/xacro">
  <!--Constant parameters-->
  <xacro:property name="torso_max_vel"  value="0.07" />
  <xacro:property name="torso_eps"      value="0.02" />

  <xacro:include filename="$(find tiago_mujoco)/assets/xacro/head.mujoco.xacro" />
  <xacro:include filename="$(find tiago_mujoco)/assets/xacro/arm.mujoco.xacro" />

  <xacro:macro name="tiago_torso" params="name arm_name" >
    <body>
      <!-- Bottom fixed part of column -->
      <body name="${name}_fixed_link" pos="-0.062 0.0 0.193" >
        <inertial mass="40.01360" pos="0.02435 -0.00464 0.15900" fullinertia="0.383411 0.405773 0.076998 0.000364 -0.024389 0.000782" />
        <geom name="${name}_torso_link"   type="mesh" mesh="torso" rgba="0.9 0.9 0.9 1" group="2" contype="0" conaffinity="0" />
        <geom pos="0.085 0.0 0.02" name="${name}_torso_link_c0" type="box" rgba="0.9 0.9 0.9 1" group="3" size="0.2 0.125 0.01" />
        <geom pos="0.0 0.0 0.05"   name="${name}_torso_link_c1" type="box" rgba="0.9 0.9 0.9 1" group="3" size="0.125 0.125 0.05" />
        <body name="${name}_lift_link" pos="0.0 0.0 0.597" >
          <inertial mass="20.93198" pos="0.04361 -0.00116 -0.17334" fullinertia="0.24487 0.249269 0.090395 -0.001456 -0.009742 0.008281" />
          <joint name="${name}_lift_joint" type="slide" axis="0 0 1" limited="true" range="0 0.35" damping="0.5" frictionloss="1"/>
          <geom name="${name}_lift" rgba="1 1 1 1" type="mesh" mesh="torso_lift_with_arm" group="2" contype="0" conaffinity="0" />
          <geom name="${name}_lift_c0" rgba="1 1 1 1" type="mesh" mesh="torso_lift_with_arm_c0" group="3" />
          <geom name="${name}_lift_c1" rgba="1 1 1 1" type="mesh" mesh="torso_lift_with_arm_c1" group="3" />
          <geom name="${name}_lift_c2" rgba="1 1 1 1" type="mesh" mesh="torso_lift_with_arm_c2" group="3" />

          <xacro:head name="${name}" />

          <xacro:if value="${has_arm == True}">
            <xacro:tiago_arm name="${arm_name}" xyz="0.15505 0.014 -0.151" quat="0.7071068 0 0 -0.7071068" wrist_model="${wrist_model}" has_ft_sensor="${has_ft_sensor}" reflect="1" />
          </xacro:if>

        </body>
      </body>
      <!-- Middle extending -->
      <body name="${name}_fixed_column_link" pos="-0.062 0 0.195" >
        <inertial mass="0.01" pos="0 0 0" diaginertia="0.000001 0.000001 0.000001" />
        <geom name="fixed_column"   pos="0 0 0.275" type="box" size="0.09 0.1 0.275" rgba="0. 0. 0. 1" group="2" contype="0" conaffinity="0" />
        <geom name="fixed_column_c" pos="0 0 0.275" type="box" size="0.09 0.1 0.275" rgba="0. 0. 0. 1" group="3" />
      </body>
    </body>
  </xacro:macro>
</mujoco>